<?xml version="1.0" ?>
<!-- =================================================================================== -->
<!-- |    This document was autogenerated by xacro from rebearm.urdf.xacro             | -->
<!-- |    EDITING THIS FILE BY HAND IS NOT RECOMMENDED                                 | -->
<!-- =================================================================================== -->
<!-- |    Manually replace package://rebearm_description/meshes ->  assets             | -->
<!-- =================================================================================== -->
<!-- Revolute-Revolute Manipulator -->
<robot name="rebearm">
  <material name="black">
    <color rgba="0.0 0.0 0.0 0.9"/>
  </material>
  <material name="blue">
    <color rgba="0.0 0.0 0.8 1.0"/>
  </material>
  <material name="green">
    <color rgba="0.0 0.8 0.0 1.0"/>
  </material>
  <material name="grey">
    <color rgba="0.2 0.2 0.2 0.9"/>
  </material>
  <material name="orange">
    <color rgba="1.0 0.4235294117647059 0.0392156862745098 0.9"/>
  </material>
  <material name="brown">
    <color rgba="0.8705882352941177 0.8117647058823529 0.7647058823529411 0.9"/>
  </material>
  <material name="red">
    <color rgba="0.8 0.0 0.0 1.0"/>
  </material>
  <material name="yellow">
    <color rgba="1.0 1.0 0.0 0.9"/>
  </material>
  <material name="white">
    <color rgba="1.0 1.0 1.0 0.9"/>
  </material>

  <!-- Base Link -->
  <link name="link0">
    <collision>
      <origin rpy="0.0 0.0 0.0" xyz="-0.049 -0.09 0.0"/>
      <geometry>
        <mesh filename="assets/URDF_joint0.stl" scale="0.001 0.001 0.001"/>
      </geometry>
    </collision>
    <visual>
      <origin rpy="0.0 0.0 0.0" xyz="-0.049 -0.09 0.0"/>
      <geometry>
        <mesh filename="assets/URDF_joint0.stl" scale="0.001 0.001 0.001"/>
      </geometry>
      <material name="grey"/>
    </visual>
    <inertial>
      <origin rpy="0.0 0.0 0.0" xyz="-0.049 -0.09 0.0"/>
      <mass value="0.147"/>
      <inertia ixx="0.000114686" ixy="-4.59787e-07" ixz="4.97151e-06" iyy="0.000136117" iyz="9.75275e-08" izz="0.000130364"/>
    </inertial>
  </link>
  <!-- Joint 1, z origin = parent height -->
  <joint name="shoulder_pan" type="revolute">
    <parent link="link0"/>
    <child link="link1"/>
    <origin rpy="0.0 0.0 0.0" xyz="0.0 0.0 0.04"/>
    <axis xyz="0 0 1"/>
    <dynamics damping="0.7"/>
    <limit effort="10" lower="-1.57" upper="1.57" velocity="4.8"/>
  </joint>
  <!-- Link 1-->
  <link name="link1">
    <collision>
      <origin rpy="0.0 0.0 0.0" xyz="-0.02 -0.066 0.0"/>
      <geometry>
        <mesh filename="assets/URDF_joint1.stl" scale="0.001 0.001 0.001"/>
      </geometry>
    </collision>
    <visual>
      <origin rpy="0.0 0.0 0" xyz="-0.02 -0.066 0.0"/>
      <geometry>
        <mesh filename="assets/URDF_joint1.stl" scale="0.001 0.001 0.001"/>
      </geometry>
      <material name="white"/>
    </visual>
    <inertial>
      <origin rpy="0.0 0.0 0.0" xyz="-0.02 -0.066 0.0"/>
      <mass value="0.147"/>
      <inertia ixx="0.020208333333333335" ixy="0.0" ixz="0.0" iyy="0.020208333333333335" iyz="0.0" izz="0.006666666666666668"/>
    </inertial>
  </link>
  <!-- Joint 2, z origin = parent height -->
  <joint name="shoulder_lift" type="revolute">
    <parent link="link1"/>
    <child link="link2"/>
    <origin rpy="0.0 0.0 0.0" xyz="0.0 0.0 0.038"/>
    <filename xyz="-1 0 0"/>
    <dynamics damping="0.7"/>
    <limit effort="10" lower="-1.57" upper="1.57" velocity="4.8"/>
  </joint>
  <!-- Link 2-->
  <link name="link2">
    <collision>
      <origin rpy="0.0 0.0 0.0" xyz="-0.022 -0.058 -0.01"/>
      <geometry>
        <mesh filename="assets/URDF_joint2.stl" scale="0.001 0.001 0.001"/>
      </geometry>
    </collision>
    <visual>
      <origin rpy="0.0 0.0 0.0" xyz="-0.022 -0.058 -0.01"/>
      <geometry>
        <mesh filename="assets/URDF_joint2.stl" scale="0.001 0.001 0.001"/>
      </geometry>
      <material name="orange"/>
    </visual>
    <inertial>
      <origin rpy="0.0 0.0 0.0" xyz="-0.022 -0.058 -0.01"/>
      <mass value="0.150"/>
      <inertia ixx="0.03136666666666666" ixy="0.0" ixz="0.0" iyy="0.03136666666666666" iyz="0.0" izz="0.006666666666666668"/>
    </inertial>
  </link>
  <!-- Joint 3, z origin = parent height  -->
  <joint name="elbow_flex" type="revolute">
    <parent link="link2"/>
    <child link="link3"/>
    <origin rpy="0.0 0.0 0.0" xyz="0.0 0.0 0.088"/>
    <axis xyz="1 0 0"/>
    <dynamics damping="0.7"/>
    <limit effort="10" lower="-1.57" upper="1.57" velocity="4.8"/>
  </joint>
  <!-- Link 3 -->
  <link name="link3">
    <collision>
      <origin rpy="0.0  0.0 3.141592653589793" xyz="0.022 0.048 -0.01"/>
      <geometry>
        <mesh filename="assets/URDF_joint3.stl" scale="0.001 0.001 0.001"/>
      </geometry>
    </collision>
    <visual>
      <origin rpy="0.0 0.0 3.141592653589793" xyz="0.022 0.048 -0.01"/>
      <geometry>
        <mesh filename="assets/URDF_joint3.stl" scale="0.001 0.001 0.001"/>
      </geometry>
      <material name="green"/>
    </visual>
    <inertial>
      <origin rpy="0.0 0.0 0.0" xyz="0.022 0.048 -0.01"/>
      <mass value="0.210"/>
      <inertia ixx="0.01666666666666667" ixy="0.0" ixz="0.0" iyy="0.01666666666666667" iyz="0.0" izz="0.006666666666666668"/>
    </inertial>
  </link>
  <!-- Joint 4, z origin = parent height  -->
  <joint name="wrist_flex" type="revolute">
    <origin rpy="0 0 0" xyz="0.0 -0.0002 0.112"/>
    <parent link="link3"/>
    <child link="link4"/>
    <axis xyz="1 0 0"/>
    <dynamics damping="0.7"/>
    <limit effort="10" lower="-1.57" upper="1.57" velocity="4.8"/>
  </joint>
  <!-- Link 4 -->
  <link name="link4">
    <collision>
      <origin rpy="0.0 0.0 0.0" xyz="-0.024 -0.086 -0.01"/>
      <geometry>
        <mesh filename="assets/URDF_joint4.stl" scale="0.001 0.001 0.001"/>
      </geometry>
    </collision>
    <visual>
      <origin rpy="0.0 0.0 0.0" xyz="-0.024 -0.086 -0.01"/>
      <geometry>
        <mesh filename="assets/URDF_joint4.stl" scale="0.001 0.001 0.001"/>
      </geometry>
      <material name="yellow"/>
    </visual>
    <inertial>
      <origin rpy="0.0 0.0 0.0" xyz="-0.024 -0.086 -0.01"/>
      <mass value="0.250"/>
      <inertia ixx="0.003685416666666667" ixy="0.0" ixz="0.0" iyy="0.003685416666666667" iyz="0.0" izz="0.006666666666666668"/>
    </inertial>
  </link>
  <!-- Joint 5, z origin = parent height  -->
  <joint name="wrist_roll" type="revolute">
    <origin rpy="0.0 0.0 0.0" xyz="0.0 -0.012 0.06"/>
    <parent link="link4"/>
    <child link="link5"/>
    <axis xyz="0 0 1"/>
    <dynamics damping="0.7"/>
    <limit effort="10" lower="-1.57" upper="1.57" velocity="4.8"/>
  </joint>

  <!-- Link 5, gripper base -->
  <link name="link5">
    <collision>
      <origin rpy="0.0 0.0 0.0" xyz="-0.024 -0.0332 0.0"/>
      <geometry>
        <mesh filename="assets/URDF_joint5.stl" scale="0.001 0.001 0.001"/>
      </geometry>
    </collision>
    <visual>
      <origin rpy="0.0 0.0 0.0 " xyz="-0.024 -0.0332 0.0"/>
      <geometry>
        <mesh filename="assets/URDF_joint5.stl" scale="0.001 0.001 0.001"/>
      </geometry>
      <material name="blue"/>
    </visual>
    <inertial>
      <origin rpy="0.0 0.0 0.0" xyz="-0.024 -0.0332 0.0"/>
      <mass value="0.350"/>
      <inertia ixx="0.003685416666666667" ixy="0.0" ixz="0.0" iyy="0.003685416666666667" iyz="0.0" izz="0.006666666666666668"/>
    </inertial>
  </link>

  <!-- Joint 6, z origin = parent height  -->
  <joint name="gripper" type="revolute">
    <origin rpy="0.0 0.0 0.0" xyz="0.0 -0.014 0.0356"/>
    <parent link="link5"/>
    <child link="gripper_moving_link"/>
    <axis xyz="1 0 0"/>
    <dynamics damping="0.7"/>
    <limit effort="10" lower="-1.57" upper="1.57" velocity="4.8"/>
  </joint>

  <!-- Link 6, gripper mover -->
  <link name="gripper_moving_link">
    <collision>
      <origin rpy="1.5707963267948966 0.0 0.0" xyz="-0.024 0.01 -0.01"/>
      <geometry>
        <mesh filename="assets/URDF_joint6.stl" scale="0.001 0.001 0.001"/>
      </geometry>
    </collision>
    <visual>
      <origin rpy="1.5707963267948966 0.0 0.0" xyz="-0.024 0.01 -0.01"/>
      <geometry>
        <mesh filename="assets/URDF_joint6.stl" scale="0.001 0.001 0.001"/>
      </geometry>
      <material name="blue"/>
    </visual>
    <inertial>
      <origin rpy="0.0 0.0 0.0" xyz="-0.024 0.01 -0.01"/>
      <mass value="0.210"/>
      <inertia ixx="0.003685416666666667" ixy="0.0" ixz="0.0" iyy="0.003685416666666667" iyz="0.0" izz="0.006666666666666668"/>
    </inertial>
  </link>

  <!-- Gripper frame (dummy link + fixed joint) -->
  <link name="gripper_frame_link">
    <origin xyz="0 0 0" rpy="0 -0 0"/>
    <inertial>
      <origin xyz="0 0 0" rpy="0 0 0"/>
      <mass value="1e-9"/>
      <inertia ixx="0" ixy="0" ixz="0" iyy="0" iyz="0" izz="0"/>
    </inertial>
  </link>

  <joint name="gripper_frame_joint" type="fixed">
    <origin xyz="-0.0079 -0.000218121 -0.0981274" rpy="0 3.14159 0"/>
    <parent link="link5"/>
    <child link="gripper_frame_link"/>
    <axis xyz="0 0 0"/>
  </joint>

</robot>
